<?xml version='1.0'?>
<sdf version='1.4'>
	<model name="myrobot">
		<static>false</static>
		<link name='base_link'>
			<pose>0.0 0.0 0.1 0 0.0 0.0</pose>
			
			<visual name='visual'>
				<pose>0.0 0.0 0.0 0.0 0.0 0.0</pose>
				<geometry>
					<box>
						<size>0.2 0.1 0.08</size>
					</box>
				</geometry>
			</visual>
			
			<collision name='collision'>
				<geometry>
					<box>
						<size>0.2 0.1 0.08</size>
					</box>
				</geometry>
			</collision>
			
			<inertial>
				<mass>10.0</mass>
				<pose>0.0 0.0 0.04 0.0 0.0 0.0</pose>
				<inertia>
					<ixx>0.5</ixx>
					<iyy>1.0</iyy>
					<izz>0.1</izz>
				</inertia>
			</inertial>
			
			<visual name='caster_visual'>
				<pose> -0.07 0.0 -0.04 0.0 0.0 0.0</pose>
				<geometry>
					<sphere>
						<radius>0.03</radius>
					</sphere>
				</geometry>
			</visual>
			
			<collision name='caster_collision'>
				<pose>-0.07 0.0 -0.04 0.0 0.0 0.0</pose>
				<geometry>
					<sphere>
						<radius>.03</radius>
					</sphere>
				</geometry>
				
				<surface>
					<friction>
						<ode>
							<mu>0</mu>
							<mu2>0</mu2>
							<spli1>1.0</spli1>
							<spli2>1.0</spli2>
						</ode>
					</friction>
				</surface>
			</collision>
		</link>
		
		<link name="left_wheel_link">
			<pose>0.05 0.06 0.08 0.0 1.5707 1.5707</pose>
			<visual name="visual">
				<geometry>
					<cylinder>
						<radius>0.05</radius>
						<length>0.03</length>
					</cylinder>
				</geometry>
			</visual>
			
			<collision name="collision">
				<geometry>
					<cylinder>
						<radius>0.05</radius>
						<length>0.03</length>
					</cylinder>
				</geometry>
			</collision>
		</link>
		
		<link name="right_wheel_link">
			<pose>0.05 -0.06 0.08 0 1.5707 1.5707</pose>
			<visual name="visual">
				<geometry>
					<cylinder>
						<radius>0.05</radius>
						<length>0.03</length>
					</cylinder>
				</geometry>
			</visual>
			
			<collision name="collision">
				<geometry>
					<cylinder>
						<radius>0.05</radius>
						<length>0.03</length>
					</cylinder>
				</geometry>
			</collision>
		</link>
		
		<joint name="left_wheel_joint" type ="revolute">
			<pose>0.0 0.0 -0.03 0.0 0.0 0.0</pose>
			<parent>base_link</parent>
			<child>left_wheel_link</child>
			<axis>
				<xyz> 0 1 0</xyz>
			</axis>
		</joint>
		
		<joint name="right_wheel_joint" type ="revolute">
			<pose>0.0 0.0 0.03 0.0 0.0 0.0</pose>
			<parent>base_link</parent>
			<child>right_wheel_link</child>
			<axis>
				<xyz> 0 1 0</xyz>
			</axis>
		</joint>
		
		<include>
			<uri>model://hokuyo</uri>
			<pose>0.05 0.0 0.14 0.0 0.0 3.141</pose>
		</include>
		<joint name="hokyo_joint" type="fixed">
			<child>hokuyo::link</child>
			<parent>base_link</parent>
		</joint>
		
		<plugin name="differential_drive_controller" filename="libgazebo_ros_diff_drive.so">
			<updateRate>100</updateRate>
			<alwaysOn>true</alwaysOn>
			<!-- left these default because i have a suspision they will be reused by the actul turtlebot-->
			<!-- Name of left joint, defaults to 'left_joint' -->
			<leftJoint>left_wheel_joint</leftJoint>
			
			<!-- Name of right joint, defaults to 'right_joint' -->
			<rightJoint>right_wheel_joint</rightJoint>
			
			<!-- The distance from the center of one wheel to the other, in meters, defaults to 0.34 m -->
			<wheelSeparation>0.4</wheelSeparation>
			
			<!-- Diameter of the wheels, in meters, defaults to 0.15 m -->
			<wheelDiameter>0.2</wheelDiameter>
			
			<!-- Wheel acceleration, in rad/s^2, defaults to 0.0 rad/s^2 -->
			<wheelAcceleration>0.03</wheelAcceleration>
			
			<!-- Maximum torque which the wheels can produce, in Nm, defaults to 5 Nm -->
			<wheelTorque>0.5</wheelTorque>
			
			<!-- Topic to receive geometry_msgs/Twist message commands, defaults to `cmd_vel` -->
			<commandTopic>cmd_vel</commandTopic>
			
			<!-- Topic to publish nav_msgs/Odometry messages, defaults to `odom` -->
			<odometryTopic>odom</odometryTopic>
			
			<!-- Odometry frame, defaults to `odom` -->
			<odometryFrame>odom</odometryFrame>	
			
			<!-- Robot frame to calculate odometry from, defaults to `base_footprint` -->
			<robotBaseFrame>base_link</robotBaseFrame>
			
			<!-- Odometry source, 0 for ENCODER, 1 for WORLD, defaults to WORLD -->
			<odometrySource>1</odometrySource>
            
			<!-- Set to true to publish transforms for the wheel links, defaults to false -->
			<publishWheelTF>true</publishWheelTF>
			
			<!-- Set to true to publish transforms for the odometry, defaults to true -->
			<publishOdom>true</publishOdom>
			
			<!-- Set to true to publish sensor_msgs/JointState on /joint_states for the wheel joints, defaults to false -->
			<publishWheelJointState>true</publishWheelJointState>
			
			<!-- Set to true to swap right and left wheels, defaults to true -->
			<legacyMode>false</legacyMode>
		</plugin>
	</model>
</sdf>
			
